Workbook

Sheet Overview
A1: AI Systems — Production Cost Overview
A2: OrderAssist browser extension + AI Admission Assistant. All costs in INR (source FX rate on each tab). Prepared for director review, 2026-07-30.
A4: What's in this workbook
A5: Tab | B5: What it covers
A6: Browser Extension | B6: The OrderAssist catalogue-matching extension only: current model (fully self-hosted, ₹0 API), and its own server/infra cost across 4 hosting providers.
A7: Admission Bot | B7: The AI Admission Assistant: current model + cost today, then production cost at a 6,000-student floor — split into the current Sarvam API-based method vs. a full self-hosted alternative, with a side-by-side comparison and the recommended route.
A9: Bottom line
A10: Metric | B10: INR | C10: USD (reference) | D10: Tab
A11: Browser extension, first year (cheapest host — Hetzner) | B11: ='Browser Extension'!G23 -> 46683.51 | C11: ='Browser Extension'!F23 -> 487.76 | D11: Browser Extension
A12: Admission bot, current (pilot on a laptop — not yet in production) | B12: ='Admission Bot'!B9 -> 0 | C12: — | D12: Admission Bot
A13: Admission bot, production Method 1 — Sarvam API-based (recommended) | B13: ='Admission Bot'!E26 -> 448691.83 | C13: ='Admission Bot'!E26/'Admission Bot'!B8 -> 4688.035 | D13: Admission Bot
A14: Admission bot, production Method 2 — full self-hosted (Qwen3-14B, replaces Sarvam) | B14: ='Admission Bot'!E39 -> 681818.9 | C14: ='Admission Bot'!E39/'Admission Bot'!B8 -> 7123.8 | D14: Admission Bot
A15: Combined total, first year (extension + admission bot, Method 1) | B15: =B11+B13 -> 495375.34 | D15: Calculated
A17: Recommended route: Method 1 (Sarvam API-based, current architecture) — cheaper AND higher answer quality than self-hosting a bigger local model. See Admission Bot tab for the full comparison and reasoning.

Sheet Browser Extension
A1: Browser Extension — Model & Infra Cost
A2: OrderAssist catalogue-matching flow only (Send-click → match → note). Excludes the admission bot entirely.
A4: Current model
A5: Fully self-hosted: nomic-embed-text (catalogue matching) + Ollama gemma2:2b (complementary suggestion + note generation). External API cost: ₹0 — backend/catalogue.py forces allow_cloud=False for this flow, so it never calls Sarvam.
A7: FX rate used on this tab
A8: USD → INR | B8: 95.71 | C8: Source: Xe / exchangerates.org.uk, spot rate 2026-07-28 (closest confirmed date to today)
A10: Server / infra cost (recurring)
A11: Provider | B11: Spec | C11: Compute $/mo | D11: Storage $/mo | E11: Total $/mo | F11: Total ₹/mo | G11: Total ₹/year
A12: Hetzner Cloud — CPX32 | B12: 4 vCPU / 8 GB, 160 GB NVMe (bundled) | C12: 39.23 | D12: 0 | E12: =C12+D12 -> 39.23 | F12: =E12*$B$8 -> 3754.7033 | G12: =E12*12*$B$8 -> 45056.44
A13: DigitalOcean — General Purpose 8GB | B13: 2 vCPU / 8 GB, storage bundled | C13: 42 | D13: 0 | E13: =C13+D13 -> 42 | F13: =E13*$B$8 -> 4019.82 | G13: =E13*12*$B$8 -> 48237.84
A14: AWS EC2 t3.large + EBS gp3 | B14: 2 vCPU / 8 GB + 40 GB gp3 | C14: 60.74 | D14: 3.2 | E14: =C14+D14 -> 63.94 | F14: =E14*$B$8 -> 6119.6974 | G14: =E14*12*$B$8 -> 73436.369
A15: GCP e2-standard-2 + Persistent Disk | B15: 2 vCPU / 8 GB + 40 GB pd-balanced | C15: 48.92 | D15: 4.4 | E15: =C15+D15 -> 53.32 | F15: =E15*$B$8 -> 5103.2572 | G15: =E15*12*$B$8 -> 61239.086
A17: One-time setup costs
A18: Item | B18: Cost $ | C18: Cost ₹
A19: Chrome Web Store developer registration (one-time, ever) | B19: 5 | C19: =B19*$B$8 -> 478.55
A20: Domain name (optional, renews annually) | B20: 12 | C20: =B20*$B$8 -> 1148.52
A22: Total first year (cheapest host — Hetzner)
A23: Total, first year | F23: =E12*12+B19+B20 -> 487.76 | G23: =F23*$B$8 -> 46683.51

Sheet Admission Bot
A1: Admission Bot — Current Cost & Production Cost | B1: Admission Bot — Model, Current Cost & Production Cost | C1: Admission Bot — Model, Current Cost & Production Cost
A2: Current model + cost, then production cost at a 6,000-student floor (max not yet defined — see note below), split into the current API-based method vs. a full self-hosted alternative.
A4: Current model (today, pilot)
A5: Chat: Sarvam sarvam-30b (cloud, primary) — NOTE: Sarvam’s own current pricing page no longer lists 30B, only 105B; confirm with developer@sarvam.ai before finalizing a production budget. Fallback: gemma2:2b (local Ollama, used when SARVAM_DAILY_LIMIT is hit or Sarvam errors). Embeddings: nomic-embed-text (local). Voice: AI4Bharat indic-parler-tts (local). Cap: SARVAM_DAILY_LIMIT = 150 calls/day — a POC safety limit, not a production capacity plan.
A7: FX rate used on this tab
A8: USD → INR | B8: 95.71 | C8: Source: Xe / exchangerates.org.uk, spot rate 2026-07-28
A9: Current cost, per year (runs on a dev laptop today — not yet in production; ₹0 infra, API bounded by the 150/day cap) | B9: 0
A11: Production scale — inputs
A12: Students (minimum — floor for this estimate) | B12: 6000
A13: Max questions/student (worst-case ceiling) | B13: 10
A14: % of questions in Hindi/Marathi (worst-case share) | B14: 0.45
A15: FAQ-cache hit rate assumed (worst case = 0%) | B15: 0
A16: Tokens/call — English input / output (estimated) | B16: 1200 | C16: 300
A17: Tokens/call — Hindi/Marathi input / output (Devanagari tokenizer inflation, estimated) | B17: 1400 | C17: 750
A18: Sarvam-105B input / output price (₹/1M tok) — confirmed live 2026-07-30 | B18: 4 | C18: 16
A20: Max enrollment is not yet defined; 6,000 is used as the floor. Sarvam API cost scales almost perfectly linearly with volume and stays small even at 10x this floor (~₹8,700/year at 60,000 students) — total cost is not sensitive to exactly where "max" lands until enrollment moves into the tens of thousands. Hosting cost (below) is flat regardless of student count, up to the box’s capacity ceiling.
A22: Method 1 — Current method, at production scale (Sarvam API-based)
A23: Line item | B23: $/hr or unit | C23: $/mo | D23: ₹/mo | E23: ₹/year
A24: Infra — g4dn.xlarge (NVIDIA T4 16GB): runs local fallback (gemma2:2b), embedding service, AI4Bharat TTS | B24: 0.526 | C24: =B24*730+6 -> 389.98 | D24: =C24*$B$8 -> 37324.986 | E24: =D24*12 -> 447899.83
A25: Sarvam API cost, worst case (from the inputs above, at Max questions/student) | E25: =((B12*B13*(1-B15))*(1-B14))*(B16*B18+C16*C18)/1000000+((B12*B13*(1-B15))*B14)*(B17*B18+C17*C18)/1000000 -> 792
A26: Total, Method 1 (₹/year) | E26: =E24+E25 -> 448691.83
A28: Method 1 sensitivity — questions/student
A29: Questions/student | B29: Total calls | C29: API cost ₹/year | D29: Total (infra + API) ₹/year
A30: 1 | B30: =B12*A30*(1-B15) -> 6000 | C30: =(B30*(1-B14))*(B16*B18+C16*C18)/1000000+(B30*B14)*(B17*B18+C17*C18)/1000000 -> 79.2 | D30: =E24+C30 -> 447979.03
A31: 3 | B31: =B12*A31*(1-B15) -> 18000 | C31: =(B31*(1-B14))*(B16*B18+C16*C18)/1000000+(B31*B14)*(B17*B18+C17*C18)/1000000 -> 237.6 | D31: =E24+C31 -> 448137.43
A32: 5 | B32: =B12*A32*(1-B15) -> 30000 | C32: =(B32*(1-B14))*(B16*B18+C16*C18)/1000000+(B32*B14)*(B17*B18+C17*C18)/1000000 -> 396 | D32: =E24+C32 -> 448295.83
A33: 10 | B33: =B12*A33*(1-B15) -> 60000 | C33: =(B33*(1-B14))*(B16*B18+C16*C18)/1000000+(B33*B14)*(B17*B18+C17*C18)/1000000 -> 792 | D33: =E24+C33 -> 448691.83
A35: Method 2 — Full self-hosted (Qwen3-14B as primary, replaces Sarvam entirely)
A36: Line item | B36: $/hr or unit | C36: $/mo | D36: ₹/mo | E36: ₹/year
A37: Infra — g6.xlarge (NVIDIA L4 24GB): Qwen3-14B as primary chat model, embedding service, AI4Bharat TTS, all on one box | B37: 0.805 | C37: =B37*730+6 -> 593.65 | D37: =C37*$B$8 -> 56818.242 | E37: =D37*12 -> 681818.9
A38: API cost — none (fully self-hosted, no cloud LLM calls) | E38: 0
A39: Total, Method 2 (₹/year) | E39: =E37+E38 -> 681818.9
A40: Note: self-hosting Sarvam-105B itself (the model Method 1 actually calls) would need multi-GPU / A100-class hardware — a different, much larger cost bracket, not budgeted here. Qwen3-14B is the practical ceiling within a single-GPU budget, and it still ranks below Sarvam-105B on Indic-language benchmarks.
A42: API-based (Method 1) vs. self-hosted (Method 2)
A43: Dimension | B43: Method 1 — Sarvam API-based | C43: Method 2 — Full self-hosted
A44: Annual cost, 6,000-student floor | B44: ₹4,48,692 | C44: ₹6,81,819
A45: Answer quality (Hindi/Marathi) | B45: Best-in-class — Sarvam-105B wins ~90% of pairwise Indic-language comparisons (third-party benchmark summary) | C45: Lower — Qwen3-14B ranks top-tier among generalist open models but below Sarvam-105B on Indic-specific benchmarks
A46: Data residency | B46: Student question data leaves institution infra (cloud call) — check against any data-residency requirement | C46: No data leaves premises — full control
A47: Vendor dependency | B47: Depends on Sarvam’s uptime, pricing, and rate limits (mitigated by local fallback) | C47: None — no external vendor in the loop
A48: Ops burden | B48: Low — Sarvam handles model serving; institution only runs the fallback stack | C48: Higher — institution owns model updates, monitoring, and scaling for the primary model
...
